{
    "url": "https://api.github.com/repos/thoth-station/package-extract/issues/115",
    "repository_url": "https://api.github.com/repos/thoth-station/package-extract",
    "labels_url": "https://api.github.com/repos/thoth-station/package-extract/issues/115/labels{/name}",
    "comments_url": "https://api.github.com/repos/thoth-station/package-extract/issues/115/comments",
    "events_url": "https://api.github.com/repos/thoth-station/package-extract/issues/115/events",
    "html_url": "https://github.com/thoth-station/package-extract/issues/115",
    "id": 347684279,
    "node_id": "MDU6SXNzdWUzNDc2ODQyNzk=",
    "number": 115,
    "title": "Failed to update dependencies to their latest version",
    "user": {
        "login": "sesheta",
        "id": 33906690,
        "node_id": "MDQ6VXNlcjMzOTA2Njkw",
        "avatar_url": "https://avatars2.githubusercontent.com/u/33906690?v=4",
        "gravatar_id": "",
        "url": "https://api.github.com/users/sesheta",
        "html_url": "https://github.com/sesheta",
        "followers_url": "https://api.github.com/users/sesheta/followers",
        "following_url": "https://api.github.com/users/sesheta/following{/other_user}",
        "gists_url": "https://api.github.com/users/sesheta/gists{/gist_id}",
        "starred_url": "https://api.github.com/users/sesheta/starred{/owner}{/repo}",
        "subscriptions_url": "https://api.github.com/users/sesheta/subscriptions",
        "organizations_url": "https://api.github.com/users/sesheta/orgs",
        "repos_url": "https://api.github.com/users/sesheta/repos",
        "events_url": "https://api.github.com/users/sesheta/events{/privacy}",
        "received_events_url": "https://api.github.com/users/sesheta/received_events",
        "type": "User",
        "site_admin": false
    },
    "labels": [{
            "id": 912744631,
            "node_id": "MDU6TGFiZWw5MTI3NDQ2MzE=",
            "url": "https://api.github.com/repos/thoth-station/package-extract/labels/bot",
            "name": "bot",
            "color": "698B69",
            "default": false
        },
        {
            "id": 1015035948,
            "node_id": "MDU6TGFiZWwxMDE1MDM1OTQ4",
            "url": "https://api.github.com/repos/thoth-station/package-extract/labels/test:flake",
            "name": "test:flake",
            "color": "e2aef2",
            "default": false
        }
    ],
    "state": "open",
    "locked": false,
    "assignee": null,
    "assignees": [],
    "milestone": null,
    "comments": 0,
    "created_at": "2018-08-05T09:48:45Z",
    "updated_at": "2018-08-05T09:49:14Z",
    "closed_at": null,
    "author_association": "MEMBER",
    "body": "\nAutomatic dependency update failed for the current master with SHA be9b557b0fe752e7af98ee77c3a3fa21ef6bae89.\n\nThe automatic dependency management cannot continue. Please fix errors reported bellow.\n\n\n##### Command\n\n```\n  $ pipenv update --dev\n```\n\n<details>\n  <summary>Standard output</summary>\n\n```\nRunning $ pipenv lock then $ pipenv sync.\n\n```\n\n</details>\n\n<details>\n  <summary>Standard error</summary>\n\n```\nCreating a virtualenv for this project...\nPipfile: /tmp/tmpc4bu4uat/Pipfile\nUsing /usr/bin/python3 (3.6.6) to create virtualenv...\nAlready using interpreter /usr/bin/python3\nUsing base prefix '/usr'\nNew python executable in /tmp/tmpc4bu4uat/.venv/bin/python3\nAlso creating executable in /tmp/tmpc4bu4uat/.venv/bin/python\nInstalling setuptools, pip, wheel...\n  Complete output from command /tmp/tmpc4bu4uat/.venv/bin/python3 - setuptools pip wheel:\n  The directory '/.cache/pip/http' or its parent directory is not owned by the current user and the cache has been disabled. Please check the permissions and owner of that directory. If executing pip with sudo, you may want sudo's -H flag.\nThe directory '/.cache/pip' or its parent directory is not owned by the current user and caching wheels has been disabled. check the permissions and owner of that directory. If executing pip with sudo, you may want sudo's -H flag.\nLooking in links: /usr/local/lib/python3.6/site-packages, /usr/local/lib/python3.6/site-packages/virtualenv_support, /usr/local/lib/python3.6/site-packages/virtualenv_support\nCollecting setuptools\n  Retrying (Retry(total=4, connect=None, read=None, redirect=None, status=None)) after connection broken by 'NewConnectionError('<pip._vendor.urllib3.connection.VerifiedHTTPSConnection object at 0x7f66bfebe4a8>: Failed to establish a new connection: [Errno -2] Name or service not known',)': /packages/ff/f4/385715ccc461885f3cedf57a41ae3c12b5fec3f35cce4c8706b1a112a133/setuptools-40.0.0-py2.py3-none-any.whl\n  Retrying (Retry(total=3, connect=None, read=None, redirect=None, status=None)) after connection broken by 'NewConnectionError('<pip._vendor.urllib3.connection.VerifiedHTTPSConnection object at 0x7f66bfebe8d0>: Failed to establish a new connection: [Errno -2] Name or service not known',)': /packages/ff/f4/385715ccc461885f3cedf57a41ae3c12b5fec3f35cce4c8706b1a112a133/setuptools-40.0.0-py2.py3-none-any.whl\n  Retrying (Retry(total=2, connect=None, read=None, redirect=None, status=None)) after connection broken by 'NewConnectionError('<pip._vendor.urllib3.connection.VerifiedHTTPSConnection object at 0x7f66bfebe668>: Failed to establish a new connection: [Errno -2] Name or service not known',)': /packages/ff/f4/385715ccc461885f3cedf57a41ae3c12b5fec3f35cce4c8706b1a112a133/setuptools-40.0.0-py2.py3-none-any.whl\n  Retrying (Retry(total=1, connect=None, read=None, redirect=None, status=None)) after connection broken by 'NewConnectionError('<pip._vendor.urllib3.connection.VerifiedHTTPSConnection object at 0x7f66bfebe7b8>: Failed to establish a new connection: [Errno -2] Name or service not known',)': /packages/ff/f4/385715ccc461885f3cedf57a41ae3c12b5fec3f35cce4c8706b1a112a133/setuptools-40.0.0-py2.py3-none-any.whl\n  Retrying (Retry(total=0, connect=None, read=None, redirect=None, status=None)) after connection broken by 'NewConnectionError('<pip._vendor.urllib3.connection.VerifiedHTTPSConnection object at 0x7f66bfebe748>: Failed to establish a new connection: [Errno -2] Name or service not known',)': /packages/ff/f4/385715ccc461885f3cedf57a41ae3c12b5fec3f35cce4c8706b1a112a133/setuptools-40.0.0-py2.py3-none-any.whl\nCould not install packages due to an EnvironmentError: HTTPSConnectionPool(host='files.pythonhosted.org', port=443): Max retries exceeded with url: /packages/ff/f4/385715ccc461885f3cedf57a41ae3c12b5fec3f35cce4c8706b1a112a133/setuptools-40.0.0-py2.py3-none-any.whl (Caused by NewConnectionError('<pip._vendor.urllib3.connection.VerifiedHTTPSConnection object at 0x7f66bfebef60>: Failed to establish a new connection: [Errno -2] Name or service not known',))\n\n----------------------------------------\n...Installing setuptools, pip, wheel...done.\nTraceback (most recent call last):\n  File \"/usr/lib64/python3.6/runpy.py\", line 193, in _run_module_as_main\n    \"__main__\", mod_spec)\n  File \"/usr/lib64/python3.6/runpy.py\", line 85, in _run_code\n    exec(code, run_globals)\n  File \"/usr/local/lib/python3.6/site-packages/virtualenv.py\", line 2343, in <module>\n    main()\n  File \"/usr/local/lib/python3.6/site-packages/virtualenv.py\", line 712, in main\n    symlink=options.symlink)\n  File \"/usr/local/lib/python3.6/site-packages/virtualenv.py\", line 947, in create_environment\n    download=download,\n  File \"/usr/local/lib/python3.6/site-packages/virtualenv.py\", line 904, in install_wheel\n    call_subprocess(cmd, show_stdout=False, extra_env=env, stdin=SCRIPT)\n  File \"/usr/local/lib/python3.6/site-packages/virtualenv.py\", line 796, in call_subprocess\n    % (cmd_desc, proc.returncode))\nOSError: Command /tmp/tmpc4bu4uat/.venv/bin/python3 - setuptools pip wheel failed with error code 1\n\nVirtualenv location: /tmp/tmpc4bu4uat/.venv\nLocking [dev-packages] dependencies...\ncal/lib/python3.6/site-packages/pipenv/vendor/requirementslib/models/__init__.py\", line 8, in <module>\n    from .requirements import Requirement\n  File \"/usr/local/lib/python3.6/site-packages/pipenv/vendor/requirementslib/models/requirements.py\", line 8, in <module>\n    import requirements\n  File \"/usr/local/lib/python3.6/site-packages/pipenv/vendor/requirements/__init__.py\", line 1, in <module>\n    from .parser import parse   # noqa\n  File \"/usr/local/lib/python3.6/site-packages/pipenv/vendor/requirements/parser.py\", line 4, in <module>\n    from .requirement import Requirement\n  File \"/usr/local/lib/python3.6/site-packages/pipenv/vendor/requirements/requirement.py\", line 3, in <module>\n    from pkg_resources import Requirement as Req\nModuleNotFoundError: No module named 'pkg_resources'\n\n\n```\n\n</details>\n\n<details>\n  <summary>Environment details</summary>\n\n```\n\nKebechet version: 1.0.0\nPython version: 3.6.6\nPlatform: Linux-3.10.0-862.3.3.el7.x86_64-x86_64-with-fedora-28-Twenty_Eight\npipenv version: pipenv, version 2018.7.1\n\n\n```\n\n</details>\n\n<details>\n  <summary>Dependency graph</summary>\n\n```\nUnable to obtain dependency graph:\n\nCreating a virtualenv for this project...\nPipfile: /tmp/tmpc4bu4uat/Pipfile\nUsing /usr/bin/python3 (3.6.6) to create virtualenv...\nAlready using interpreter /usr/bin/python3\nUsing base prefix '/usr'\nNew python executable in /tmp/tmpc4bu4uat/.venv/bin/python3\nNot overwriting existing python script /tmp/tmpc4bu4uat/.venv/bin/python (you must use /tmp/tmpc4bu4uat/.venv/bin/python3)\nInstalling setuptools, pip, wheel...\n  Complete output from command /tmp/tmpc4bu4uat/.venv/bin/python3 - setuptools pip wheel:\n  The directory '/.cache/pip/http' or its parent directory is not owned by the current user and the cache has been disabled. Please check the permissions and owner of that directory. If executing pip with sudo, you may want sudo's -H flag.\nThe directory '/.cache/pip' or its parent directory is not owned by the current user and caching wheels has been disabled. check the permissions and owner of that directory. If executing pip with sudo, you may want sudo's -H flag.\nLooking in links: /usr/local/lib/python3.6/site-packages, /usr/local/lib/python3.6/site-packages/virtualenv_support, /usr/local/lib/python3.6/site-packages/virtualenv_support\nCollecting setuptools\n  Retrying (Retry(total=4, connect=None, read=None, redirect=None, status=None)) after connection broken by 'NewConnectionError('<pip._vendor.urllib3.connection.VerifiedHTTPSConnection object at 0x7faf082b3080>: Failed to establish a new connection: [Errno -2] Name or service not known',)': /packages/ff/f4/385715ccc461885f3cedf57a41ae3c12b5fec3f35cce4c8706b1a112a133/setuptools-40.0.0-py2.py3-none-any.whl\n  Retrying (Retry(total=3, connect=None, read=None, redirect=None, status=None)) after connection broken by 'NewConnectionError('<pip._vendor.urllib3.connection.VerifiedHTTPSConnection object at 0x7faf082b3a58>: Failed to establish a new connection: [Errno -2] Name or service not known',)': /packages/ff/f4/385715ccc461885f3cedf57a41ae3c12b5fec3f35cce4c8706b1a112a133/setuptools-40.0.0-py2.py3-none-any.whl\n  Retrying (Retry(total=2, connect=None, read=None, redirect=None, status=None)) after connection broken by 'NewConnectionError('<pip._vendor.urllib3.connection.VerifiedHTTPSConnection object at 0x7faf082b3b00>: Failed to establish a new connection: [Errno -2] Name or service not known',)': /packages/ff/f4/385715ccc461885f3cedf57a41ae3c12b5fec3f35cce4c8706b1a112a133/setuptools-40.0.0-py2.py3-none-any.whl\n  Retrying (Retry(total=1, connect=None, read=None, redirect=None, status=None)) after connection broken by 'NewConnectionError('<pip._vendor.urllib3.connection.VerifiedHTTPSConnection object at 0x7faf082b3438>: Failed to establish a new connection: [Errno -2] Name or service not known',)': /packages/ff/f4/385715ccc461885f3cedf57a41ae3c12b5fec3f35cce4c8706b1a112a133/setuptools-40.0.0-py2.py3-none-any.whl\n  Retrying (Retry(total=0, connect=None, read=None, redirect=None, status=None)) after connection broken by 'NewConnectionError('<pip._vendor.urllib3.connection.VerifiedHTTPSConnection object at 0x7faf082b35c0>: Failed to establish a new connection: [Errno -2] Name or service not known',)': /packages/ff/f4/385715ccc461885f3cedf57a41ae3c12b5fec3f35cce4c8706b1a112a133/setuptools-40.0.0-py2.py3-none-any.whl\nCould not install packages due to an EnvironmentError: HTTPSConnectionPool(host='files.pythonhosted.org', port=443): Max retries exceeded with url: /packages/ff/f4/385715ccc461885f3cedf57a41ae3c12b5fec3f35cce4c8706b1a112a133/setuptools-40.0.0-py2.py3-none-any.whl (Caused by NewConnectionError('<pip._vendor.urllib3.connection.VerifiedHTTPSConnection object at 0x7faf082b3630>: Failed to establish a new connection: [Errno -2] Name or service not known',))\n\n----------------------------------------\n...Installing setuptools, pip, wheel...done.\nTraceback (most recent call last):\n  File \"/usr/lib64/python3.6/runpy.py\", line 193, in _run_module_as_main\n    \"__main__\", mod_spec)\n  File \"/usr/lib64/python3.6/runpy.py\", line 85, in _run_code\n    exec(code, run_globals)\n  File \"/usr/local/lib/python3.6/site-packages/virtualenv.py\", line 2343, in <module>\n    main()\n  File \"/usr/local/lib/python3.6/site-packages/virtualenv.py\", line 712, in main\n    symlink=options.symlink)\n  File \"/usr/local/lib/python3.6/site-packages/virtualenv.py\", line 947, in create_environment\n    download=download,\n  File \"/usr/local/lib/python3.6/site-packages/virtualenv.py\", line 904, in install_wheel\n    call_subprocess(cmd, show_stdout=False, extra_env=env, stdin=SCRIPT)\n  File \"/usr/local/lib/python3.6/site-packages/virtualenv.py\", line 796, in call_subprocess\n    % (cmd_desc, proc.returncode))\nOSError: Command /tmp/tmpc4bu4uat/.venv/bin/python3 - setuptools pip wheel failed with error code 1\n\nVirtualenv location: /tmp/tmpc4bu4uat/.venv\nCreating a virtualenv for this project...\nPipfile: /tmp/tmpc4bu4uat/Pipfile\nUsing /usr/bin/python3 (3.6.6) to create virtualenv...\nAlready using interpreter /usr/bin/python3\nUsing base prefix '/usr'\nNew python executable in /tmp/tmpc4bu4uat/.venv/bin/python3\nNot overwriting existing python script /tmp/tmpc4bu4uat/.venv/bin/python (you must use /tmp/tmpc4bu4uat/.venv/bin/python3)\nInstalling setuptools, pip, wheel...\n  Complete output from command /tmp/tmpc4bu4uat/.venv/bin/python3 - setuptools pip wheel:\n  The directory '/.cache/pip/http' or its parent directory is not owned by the current user and the cache has been disabled. Please check the permissions and owner of that directory. If executing pip with sudo, you may want sudo's -H flag.\nThe directory '/.cache/pip' or its parent directory is not owned by the current user and caching wheels has been disabled. check the permissions and owner of that directory. If executing pip with sudo, you may want sudo's -H flag.\nLooking in links: /usr/local/lib/python3.6/site-packages, /usr/local/lib/python3.6/site-packages/virtualenv_support, /usr/local/lib/python3.6/site-packages/virtualenv_support\nCollecting setuptools\n  Retrying (Retry(total=4, connect=None, read=None, redirect=None, status=None)) after connection broken by 'NewConnectionError('<pip._vendor.urllib3.connection.VerifiedHTTPSConnection object at 0x7fb820a0d710>: Failed to establish a new connection: [Errno -2] Name or service not known',)': /packages/ff/f4/385715ccc461885f3cedf57a41ae3c12b5fec3f35cce4c8706b1a112a133/setuptools-40.0.0-py2.py3-none-any.whl\n  Retrying (Retry(total=3, connect=None, read=None, redirect=None, status=None)) after connection broken by 'NewConnectionError('<pip._vendor.urllib3.connection.VerifiedHTTPSConnection object at 0x7fb820a0d898>: Failed to establish a new connection: [Errno -2] Name or service not known',)': /packages/ff/f4/385715ccc461885f3cedf57a41ae3c12b5fec3f35cce4c8706b1a112a133/setuptools-40.0.0-py2.py3-none-any.whl\n  Retrying (Retry(total=2, connect=None, read=None, redirect=None, status=None)) after connection broken by 'NewConnectionError('<pip._vendor.urllib3.connection.VerifiedHTTPSConnection object at 0x7fb820a0dd68>: Failed to establish a new connection: [Errno -2] Name or service not known',)': /packages/ff/f4/385715ccc461885f3cedf57a41ae3c12b5fec3f35cce4c8706b1a112a133/setuptools-40.0.0-py2.py3-none-any.whl\n  Retrying (Retry(total=1, connect=None, read=None, redirect=None, status=None)) after connection broken by 'NewConnectionError('<pip._vendor.urllib3.connection.VerifiedHTTPSConnection object at 0x7fb820a0d9e8>: Failed to establish a new connection: [Errno -2] Name or service not known',)': /packages/ff/f4/385715ccc461885f3cedf57a41ae3c12b5fec3f35cce4c8706b1a112a133/setuptools-40.0.0-py2.py3-none-any.whl\n  Retrying (Retry(total=0, connect=None, read=None, redirect=None, status=None)) after connection broken by 'NewConnectionError('<pip._vendor.urllib3.connection.VerifiedHTTPSConnection object at 0x7fb820a0d908>: Failed to establish a new connection: [Errno -2] Name or service not known',)': /packages/ff/f4/385715ccc461885f3cedf57a41ae3c12b5fec3f35cce4c8706b1a112a133/setuptools-40.0.0-py2.py3-none-any.whl\nCould not install packages due to an EnvironmentError: HTTPSConnectionPool(host='files.pythonhosted.org', port=443): Max retries exceeded with url: /packages/ff/f4/385715ccc461885f3cedf57a41ae3c12b5fec3f35cce4c8706b1a112a133/setuptools-40.0.0-py2.py3-none-any.whl (Caused by NewConnectionError('<pip._vendor.urllib3.connection.VerifiedHTTPSConnection object at 0x7fb820a14438>: Failed to establish a new connection: [Errno -2] Name or service not known',))\n\n----------------------------------------\n...Installing setuptools, pip, wheel...done.\nTraceback (most recent call last):\n  File \"/usr/lib64/python3.6/runpy.py\", line 193, in _run_module_as_main\n    \"__main__\", mod_spec)\n  File \"/usr/lib64/python3.6/runpy.py\", line 85, in _run_code\n    exec(code, run_globals)\n  File \"/usr/local/lib/python3.6/site-packages/virtualenv.py\", line 2343, in <module>\n    main()\n  File \"/usr/local/lib/python3.6/site-packages/virtualenv.py\", line 712, in main\n    symlink=options.symlink)\n  File \"/usr/local/lib/python3.6/site-packages/virtualenv.py\", line 947, in create_environment\n    download=download,\n  File \"/usr/local/lib/python3.6/site-packages/virtualenv.py\", line 904, in install_wheel\n    call_subprocess(cmd, show_stdout=False, extra_env=env, stdin=SCRIPT)\n  File \"/usr/local/lib/python3.6/site-packages/virtualenv.py\", line 796, in call_subprocess\n    % (cmd_desc, proc.returncode))\nOSError: Command /tmp/tmpc4bu4uat/.venv/bin/python3 - setuptools pip wheel failed with error code 1\n\nVirtualenv location: /tmp/tmpc4bu4uat/.venv\nTraceback (most recent call last):\n  File \"/usr/local/bin/pipenv\", line 11, in <module>\n    sys.exit(cli())\n  File \"/usr/local/lib/python3.6/site-packages/pipenv/vendor/click/core.py\", line 722, in __call__\n    return self.main(*args, **kwargs)\n  File \"/usr/local/lib/python3.6/site-packages/pipenv/vendor/click/core.py\", line 697, in main\n    rv = self.invoke(ctx)\n  File \"/usr/local/lib/python3.6/site-packages/pipenv/vendor/click/core.py\", line 1066, in invoke\n    return _process_result(sub_ctx.command.invoke(sub_ctx))\n  File \"/usr/local/lib/python3.6/site-packages/pipenv/vendor/click/core.py\", line 895, in invoke\n    return ctx.invoke(self.callback, **ctx.params)\n  File \"/usr/local/lib/python3.6/site-packages/pipenv/vendor/click/core.py\", line 535, in invoke\n    return callback(*args, **kwargs)\n  File \"/usr/local/lib/python3.6/site-packages/pipenv/cli.py\", line 435, in install\n    selective_upgrade=selective_upgrade,\n  File \"/usr/local/lib/python3.6/site-packages/pipenv/core.py\", line 1943, in do_install\n    pypi_mirror=pypi_mirror,\n  File \"/usr/local/lib/python3.6/site-packages/pipenv/core.py\", line 1322, in do_init\n    pypi_mirror=pypi_mirror,\n  File \"/usr/local/lib/python3.6/site-packages/pipenv/core.py\", line 807, in do_install_dependencies\n    pypi_mirror=pypi_mirror,\n  File \"/usr/local/lib/python3.6/site-packages/pipenv/core.py\", line 1466, in pip_install\n    c = delegator.run(pip_command, block=block, env=pip_config)\n  File \"/usr/local/lib/python3.6/site-packages/pipenv/vendor/delegator.py\", line 280, in run\n    c.run(block=block, binary=binary, cwd=cwd, env=env)\n  File \"/usr/local/lib/python3.6/site-packages/pipenv/vendor/delegator.py\", line 164, in run\n    s = PopenSpawn(self._popen_args, **pexpect_kwargs)\n  File \"/usr/local/lib/python3.6/site-packages/pipenv/vendor/pexpect/popen_spawn.py\", line 53, in __init__\n    self.proc = subprocess.Popen(cmd, **kwargs)\n  File \"/usr/lib64/python3.6/subprocess.py\", line 709, in __init__\n    restore_signals, start_new_session)\n  File \"/usr/lib64/python3.6/subprocess.py\", line 1344, in _execute_child\n    raise child_exception_type(errno_num, err_msg, err_filename)\nFileNotFoundError: [Errno 2] No such file or directory: 'None': 'None'\n\n```\n\n</details>\n\n\n\n##### Notes\n\nFor more information, see [Pipfile](/thoth-station/package-extract/blob/be9b557b0fe752e7af98ee77c3a3fa21ef6bae89/Pipfile) and [Pipfile.lock](/thoth-station/package-extract/blob/be9b557b0fe752e7af98ee77c3a3fa21ef6bae89/Pipfile.lock).\n\nOnce this issue is resolved, the issue will be automatically closed by bot.\n\n",
    "closed_by": null
}